[32mINFO    [0m sqlalchemy.engine.Engine:base.py:2689 BEGIN (implicit)
[32mINFO    [0m sqlalchemy.engine.Engine:base.py:1848 SELECT bookmazon.password_reset_tokens.id, bookmazon.password_reset_tokens.user_email, bookmazon.password_reset_tokens.token, bookmazon.password_reset_tokens.token_status, bookmazon.password_reset_tokens.update_datetime, bookmazon.password_reset_tokens.create_datetime 
FROM bookmazon.password_reset_tokens 
WHERE bookmazon.password_reset_tokens.token = %(token_1)s
[32mINFO    [0m sqlalchemy.engine.Engine:base.py:1848 [generated in 0.00018s] {'token_1': 'NMYbtuFNj2HMzl4nprqVtl-NT5oQg75QwWDuUu-Phmw'}
[31m[1mERROR   [0m C:\Users\user\PycharmProjects\pythonProject\bookmazon\utils\logger.py:UserService.py:404 Error validating reset token: (psycopg2.errors.UndefinedTable) relation "bookmazon.password_reset_tokens" does not exist
LINE 2: FROM bookmazon.password_reset_tokens 
             ^

[SQL: SELECT bookmazon.password_reset_tokens.id, bookmazon.password_reset_tokens.user_email, bookmazon.password_reset_tokens.token, bookmazon.password_reset_tokens.token_status, bookmazon.password_reset_tokens.update_datetime, bookmazon.password_reset_tokens.create_datetime 
FROM bookmazon.password_reset_tokens 
WHERE bookmazon.password_reset_tokens.token = %(token_1)s]
[parameters: {'token_1': 'NMYbtuFNj2HMzl4nprqVtl-NT5oQg75QwWDuUu-Phmw'}]
(Background on this error at: https://sqlalche.me/e/20/f405)